<?xml version='1.0' encoding='UTF-8'?>
<robot name="kr2_robot_a810">
  <material name="gray">
    <color rgba="0.5 0.5 0.5 1.0"/>
  </material>
  <material name="dark_gray">
    <color rgba="0.3 0.3 0.3 1.0"/>
  </material>
  <material name="light_gray">
    <color rgba="0.7 0.7 0.7 1.0"/>
  </material>
  <material name="black">
    <color rgba="0.1 0.1 0.1 1.0"/>
  </material>
  <material name="orange">
    <color rgba="1.0 0.4235294117647059 0.0392156862745098 1.0"/>
  </material>
  <link name="world"/>
  <link name="base">
    <inertial>
      <origin rpy="0 0 0" xyz="0 0 0"/>
      <mass value="0.6"/>
      <inertia ixx="0.003" ixy="0.0" ixz="0.0" iyy="0.003" iyz="0.0" izz="0.003"/>
    </inertial>
    <visual>
      <origin rpy="0 0 0" xyz="0 0 0"/>
      <geometry>
        <mesh filename="./meshes/a810/a810_Base.stl" scale="0.001 0.001 0.001"/>
      </geometry>
      <material name="">
        <color rgba="0.2 0.2 0.2 1"/>
      </material>
    </visual>
    <collision>
      <origin rpy="0 0 0" xyz="0 0 0"/>
      <geometry>
        <mesh filename="./meshes/a810/a810_Base.stl" scale="0.001 0.001 0.001"/>
      </geometry>
    </collision>
  </link>
  <link name="link1">
    <inertial>
      <origin rpy="0 0 0" xyz="0 0 0.13684999999999997"/>
      <mass value="4.58"/>
      <inertia ixx="0.003" ixy="0.0" ixz="0.0" iyy="0.003" iyz="0.0" izz="0.003"/>
    </inertial>
    <visual>
      <origin rpy="0 0 0" xyz="0 0 0.169"/>
      <geometry>
        <mesh filename="./meshes/a810/a810_Link2.stl" scale="0.001 0.001 0.001"/>
      </geometry>
      <material name="">
        <color rgba="0.2 0.2 0.2 1"/>
      </material>
    </visual>
    <collision>
      <origin rpy="0 0 0" xyz="0 0 0.169"/>
      <geometry>
        <mesh filename="./meshes/a810/a810_Link2.stl" scale="0.001 0.001 0.001"/>
      </geometry>
    </collision>
  </link>
  <link name="linkJ2">
    <visual>
      <origin rpy="1.5707963267948966 0 0" xyz="0 -0.01 0"/>
      <geometry>
        <cylinder length="0.15" radius="0.015"/>
      </geometry>
      <material name="orange"/>
    </visual>
    <collision>
      <origin rpy="1.5707963267948966 0 0" xyz="0 -0.01 0"/>
      <geometry>
        <cylinder length="0.15" radius="0.015"/>
      </geometry>
    </collision>
    <inertial>
      <origin rpy="0 0 0" xyz="0 0 0"/>
      <mass value="6.1"/>
      <inertia ixx="0.003" ixy="0.0" ixz="0.0" iyy="0.003" iyz="0.0" izz="0.003"/>
    </inertial>
  </link>
  <link name="link2">
    <inertial>
      <origin rpy="0 0 0" xyz="0 0 0.17500000000000002"/>
      <mass value="0.43"/>
      <inertia ixx="0.003" ixy="0.0" ixz="0.0" iyy="0.003" iyz="0.0" izz="0.003"/>
    </inertial>
    <visual>
      <origin rpy="-1.5707963267948966 0 -1.5707963267948966" xyz="0.049 0 0"/>
      <geometry>
        <mesh filename="./meshes/a810/a810_Link3.stl" scale="0.001 0.001 0.001"/>
      </geometry>
      <material name="">
        <color rgba="0.2 0.2 0.2 1"/>
      </material>
    </visual>
    <collision>
      <origin rpy="-1.5707963267948966 0 -1.5707963267948966" xyz="0.049 0 0"/>
      <geometry>
        <mesh filename="./meshes/a810/a810_Link3.stl" scale="0.001 0.001 0.001"/>
      </geometry>
    </collision>
  </link>
  <link name="link3">
    <inertial>
      <origin rpy="0 0 0" xyz="0 0 0"/>
      <mass value="2.9"/>
      <inertia ixx="0.003" ixy="0.0" ixz="0.0" iyy="0.003" iyz="0.0" izz="0.003"/>
    </inertial>
    <visual>
      <origin rpy="1.5707963267948966 0 -1.5707963267948966" xyz="-0.05 -0.0 0.315"/>
      <geometry>
        <mesh filename="./meshes/a810/a810_Link4.stl" scale="0.001 0.001 0.001"/>
      </geometry>
      <material name="">
        <color rgba="0.2 0.2 0.2 1"/>
      </material>
    </visual>
    <collision>
      <origin rpy="1.5707963267948966 0 -1.5707963267948966" xyz="-0.05 -0.0 0.315"/>
      <geometry>
        <mesh filename="./meshes/a810/a810_Link4.stl" scale="0.001 0.001 0.001"/>
      </geometry>
    </collision>
  </link>
  <link name="linkJ4">
    <visual>
      <origin rpy="1.5707963267948966 0 0" xyz="0 0.013000000000000001 0"/>
      <geometry>
        <cylinder length="0.129" radius="0.015"/>
      </geometry>
      <material name="orange"/>
    </visual>
    <collision>
      <origin rpy="1.5707963267948966 0 0" xyz="0 0.013000000000000001 0"/>
      <geometry>
        <cylinder length="0.129" radius="0.015"/>
      </geometry>
    </collision>
    <inertial>
      <origin rpy="0 0 0" xyz="0 0.006500000000000001 0"/>
      <mass value="3.8"/>
      <inertia ixx="0.003" ixy="0.0" ixz="0.0" iyy="0.003" iyz="0.0" izz="0.003"/>
    </inertial>
  </link>
  <link name="link4">
    <inertial>
      <origin rpy="0 0 0" xyz="0 0 0.168"/>
      <mass value="0.33"/>
      <inertia ixx="0.003" ixy="0.0" ixz="0.0" iyy="0.003" iyz="0.0" izz="0.003"/>
    </inertial>
    <visual>
      <origin rpy="-1.5707963267948966 0 1.5707963267948966" xyz="0.04 0.0005 0.0"/>
      <geometry>
        <mesh filename="./meshes/a810/a810_Link5.stl" scale="0.001 0.001 0.001"/>
      </geometry>
      <material name="">
        <color rgba="0.2 0.2 0.2 1"/>
      </material>
    </visual>
    <collision>
      <origin rpy="-1.5707963267948966 0 1.5707963267948966" xyz="0.04 0.0005 0.0"/>
      <geometry>
        <mesh filename="./meshes/a810/a810_Link5.stl" scale="0.001 0.001 0.001"/>
      </geometry>
    </collision>
  </link>
  <link name="link5">
    <inertial>
      <origin rpy="0 0 0" xyz="0 0 0"/>
      <mass value="1.7"/>
      <inertia ixx="0.003" ixy="0.0" ixz="0.0" iyy="0.003" iyz="0.0" izz="0.003"/>
    </inertial>
    <visual>
      <origin rpy="0 0 -1.5707963267948966" xyz="0.0 0.002 0.1035"/>
      <geometry>
        <mesh filename="./meshes/a810/a810_Link6.stl" scale="0.001 0.001 0.001"/>
      </geometry>
      <material name="">
        <color rgba="0.2 0.2 0.2 1"/>
      </material>
    </visual>
    <collision>
      <origin rpy="0 0 -1.5707963267948966" xyz="0.0 0.002 0.1035"/>
      <geometry>
        <mesh filename="./meshes/a810/a810_Link6.stl" scale="0.001 0.001 0.001"/>
      </geometry>
    </collision>
  </link>
  <link name="linkJ6">
    <inertial>
      <origin rpy="0 0 0" xyz="0 0.004 0"/>
      <mass value="1.8"/>
      <inertia ixx="0.003" ixy="0.0" ixz="0.0" iyy="0.003" iyz="0.0" izz="0.003"/>
    </inertial>
  </link>
  <link name="link6">
    <inertial>
      <origin rpy="0 0 0" xyz="0 0 0.004"/>
      <mass value="1.8"/>
      <inertia ixx="0.003" ixy="0.0" ixz="0.0" iyy="0.003" iyz="0.0" izz="0.003"/>
    </inertial>
    <visual>
      <origin rpy="0 0 0" xyz="0.0 0.0 0.0"/>
      <geometry>
        <mesh filename="./meshes/a810/a810_Link7.stl" scale="0.001 0.001 0.001"/>
      </geometry>
      <material name="">
        <color rgba="0.2 0.2 0.2 1"/>
      </material>
    </visual>
    <collision>
      <origin rpy="0 0 0" xyz="0.0 0.0 0.0"/>
      <geometry>
        <mesh filename="./meshes/a810/a810_Link7.stl" scale="0.001 0.001 0.001"/>
      </geometry>
    </collision>
  </link>
  <link name="end_effector">
    <visual>
      <origin rpy="0 0 0" xyz="0.0 -0.0 0.0"/>
      <geometry>
        <mesh filename="./meshes/a810/a810_ToolIO.stl" scale="0.001 0.001 0.001"/>
      </geometry>
      <material name="">
        <color rgba="0.8 0.8 0.8 1"/>
      </material>
    </visual>
    <collision>
      <origin rpy="0 0 0" xyz="0.0 -0.0 0.0"/>
      <geometry>
        <mesh filename="./meshes/a810/a810_ToolIO.stl" scale="0.001 0.001 0.001"/>
      </geometry>
    </collision>
    <inertial>
      <origin rpy="0 0 0" xyz="0 0 -0.0197"/>
      <mass value="0.56"/>
      <inertia ixx="0.003" ixy="0.0" ixz="0.0" iyy="0.003" iyz="0.0" izz="0.003"/>
    </inertial>
  </link>
  <joint name="dummy" type="fixed">
    <parent link="world"/>
    <child link="base"/>
  </joint>
  <joint name="joint_1" type="revolute">
    <parent link="base"/>
    <child link="link1"/>
    <origin rpy="0 0 0" xyz="0 0 0.035"/>
    <axis xyz="0 0 1"/>
    <dynamics damping="0.1"/>
    <limit effort="204" lower="-6.283185307179586" upper="6.283185307179586" velocity="3.9269908169872414"/>
  </joint>
  <joint name="joint_2" type="revolute">
    <parent link="link1"/>
    <child link="linkJ2"/>
    <origin rpy="0 0 0" xyz="0.05 0.0 0.27369999999999994"/>
    <axis xyz="0 1 0"/>
    <dynamics damping="0.1"/>
    <limit effort="204" lower="-1.2217304763960306" upper="3.141592653589793" velocity="3.9269908169872414"/>
  </joint>
  <joint name="jointPL2" type="fixed">
    <parent link="linkJ2"/>
    <child link="link2"/>
    <origin rpy="0 0 0" xyz="-0.05 -0.0857 0"/>
  </joint>
  <joint name="joint_3" type="revolute">
    <parent link="link2"/>
    <child link="link3"/>
    <origin rpy="0 0 0" xyz="0 0 0.274"/>
    <axis xyz="0 0 1"/>
    <dynamics damping="0.1"/>
    <limit effort="85" lower="-6.283185307179586" upper="6.283185307179586" velocity="3.9269908169872414"/>
  </joint>
  <joint name="joint_4" type="revolute">
    <parent link="link3"/>
    <child link="linkJ4"/>
    <origin rpy="0 0 0" xyz="0.04 0.0 0.1429"/>
    <axis xyz="0 1 0"/>
    <dynamics damping="0.1"/>
    <limit effort="85" lower="-1.2217304763960306" upper="3.141592653589793" velocity="3.9269908169872414"/>
  </joint>
  <joint name="jointPL4" type="fixed">
    <parent link="linkJ4"/>
    <child link="link4"/>
    <origin rpy="0 0 0" xyz="-0.04 0.08405 0.0"/>
  </joint>
  <joint name="joint_5" type="revolute">
    <parent link="link4"/>
    <child link="link5"/>
    <origin rpy="0 0 0" xyz="0 0 0.271"/>
    <axis xyz="0 0 1"/>
    <dynamics damping="0.1"/>
    <limit effort="51" lower="-6.283185307179586" upper="6.283185307179586" velocity="3.9269908169872414"/>
  </joint>
  <joint name="joint_6" type="revolute">
    <parent link="link5"/>
    <child link="linkJ6"/>
    <origin rpy="0 0 0" xyz="0 0 0.10350000000000001"/>
    <axis xyz="0 1 0"/>
    <dynamics damping="0.1"/>
    <limit effort="51" lower="-6.283185307179586" upper="6.283185307179586" velocity="3.9269908169872414"/>
  </joint>
  <joint name="jointPL6" type="fixed">
    <parent link="linkJ6"/>
    <child link="link6"/>
    <origin rpy="0 0 0" xyz="0 0.111 0"/>
  </joint>
  <joint name="joint_7" type="revolute">
    <parent link="link6"/>
    <child link="end_effector"/>
    <origin rpy="0 0 0" xyz="0 0 0.108"/>
    <axis xyz="0 0 1"/>
    <dynamics damping="0.1"/>
    <limit effort="51" lower="-6.283185307179586" upper="6.283185307179586" velocity="3.9269908169872414"/>
  </joint>
</robot>
